<mujoco>
    <option timestep="0.01" integrator="RK4" gravity="0 0 -9.81">
        <flag gravity="enable" sensornoise="enable"/>
    </option>
    <visual>
        <rgba haze="0.5 0.5 0.5 1"/>
        <global offwidth="1920" offheight="1080" elevation="-20" azimuth="120"/>
    </visual>
    <asset>
        <texture type="skybox" builtin="gradient" rgb1="0.4 0.6 0.8" rgb2="0 0 0" width="32" height="512"/>
        <texture name="grid" type="2d" builtin="checker" rgb1="0.2 0.3 0.4" rgb2="0.1 0.2 0.3" width="512" height="512"/>
        <material name="grid" texture="grid" texrepeat="1 1" texuniform="true" reflectance="0.2"/>
      </asset>
    <worldbody>
        <geom name="floor" size="0 0 0.01" type="plane" material="grid" condim="1" solref="1 0.1"/>
        <light name="floorlight" mode="fixed" pos="0 0 50" dir="0 0 -1" diffuse="0.8 0.8 0.8" specular="0.3 0.3 0.3"/>
        <body pos="0 0 2" euler="0 180 0">
            <joint name="pin" type="hinge" axis="0 -1 0" pos="0 0 0.5"/>
            <geom type="cylinder" size=".05 .5" rgba="0 .9 0 1" mass="1"/>
            <camera name="fixed" pos="0 -.6 .3" xyaxes="1 0 0 0 1 2"/>
            <camera name="track" pos="0 -3 1" xyaxes="1 0 0 0 1 2" mode="track"/>
        </body>
    </worldbody>
    <actuator>
        <motor joint="pin" name="torque" gear="1" ctrllimited="true" ctrlrange="-100 100" />
        <position name="position_servo" joint="pin" kp="10" />
        <velocity name="velocity_servo" joint="pin" kv="0" />
    </actuator>
    <sensor>
        <jointpos joint="pin" noise="0.2" />
        <jointvel joint="pin" noise="1" />
    </sensor>
</mujoco>